<?xml version="1.0" ?>

<robot name="exarm">

    <material name="black">
        <color rgba="0 0 0 1" />
    </material>

    <material name="red">
        <color rgba="1 0 0 1" />
    </material>

    <material name="blue">
        <color rgba="0 0 1 1" />
    </material>

    <material name="green">
        <color rgba="0 1 0 1" />
    </material>

    <link name="base_link" />

    <link name="link_0" >
        <visual>
            <geometry>
                <box size="0.5 0.5 0.1" />
            </geometry>
            <material name="black"/>
        </visual>
    </link>

    <joint name="joint_0" type="fixed">
        <parent link="base_link"/>
        <child link="link_0" />
        <origin xyz="0 0 0.05" rpy="0 0 0" /> 
    </joint>

    <link name="link_1" >
        <visual>
            <origin xyz="0 0 0.2" rpy="0 0 0" />
            <geometry>
                <box size="0.1 0.05 0.6" />
            </geometry>
            <material name="blue"/>
        </visual>
    </link>

    <joint name="joint_1" type="revolute">
        <parent link="link_0"/>
        <child link="link_1" />
        <origin xyz="0 0 0.15" rpy="0 0 0" />
        <axis xyz="0 0 1" />
        <limit lower="-3.1415" upper="3.1415" effort="40" velocity="2.0" />
    </joint>

    <link name="link_2" >
        <visual>
            <origin xyz="0 0 0.2" rpy="0 0 0" />
            <geometry>
                <box size="0.1 0.05 0.6" />
            </geometry>
            <material name="green"/>
        </visual>
    </link>

    <joint name="joint_2" type="revolute">
        <parent link="link_1"/>
        <child link="link_2" />
        <origin xyz="0 0.05 0.4" rpy="0 0 0" />
        <axis xyz="0 1 0" />
        <limit lower="-2.0" upper="2.0" effort="40" velocity="2.0" />
    </joint>

    <link name="link_3" >
        <visual>
            <origin xyz="0 0 0.2" rpy="0 0 0" />
            <geometry>
                <box size="0.1 0.05 0.6" />
            </geometry>
            <material name="red"/>
        </visual>
    </link>

    <joint name="joint_3" type="revolute">
        <parent link="link_2"/>
        <child link="link_3" />
        <origin xyz="0 -0.05 0.4" rpy="0 0 0" />
        <axis xyz="0 1 0" />
        <limit lower="-2.0" upper="2.0" effort="40" velocity="2.0" />
    </joint>

</robot>